<?xml version="1.0" encoding="utf-8" ?>
<robot name="panda">
	<!-- Panda link 0 -->
    <link name="panda_link0">
        <visual>
            <geometry>
                <mesh filename="franka/Franka_Link0_assy OBJ/Franka_Link0_assy.obj" />
				<!--<mesh filename="asset/panda/link0.stl" />-->
            </geometry>
        </visual>
        <inertial>
            <origin rpy="0 0 0" xyz="0 0 0" />
            <mass value="2.9411" />
			<inertia ixx="0.00315" ixy="0.0" ixz="0.0" iyy="0.00388" iyz="0.0" izz="0.004285" />
        </inertial>
    </link>
    <!-- Joint 1 from link 0 to 1 -->
    <joint name="panda_joint1" type="revolute">
        <origin rpy="0 0 0" xyz="0 0 0.333" />
        <parent link="panda_link0" />
        <child link="panda_link1" />
        <axis xyz="0 0 1" />
        <!-- <limit effort="87" lower="-2.8973" upper="2.8973" velocity="2.1750" /> -->
        <dynamics damping="1.0" friction="10" />
    </joint>
    <!-- Panda link 1 -->
    <link name="panda_link1">
        <visual>
            <geometry>
                <mesh filename="franka/Franka_Link1_assy OBJ/Franka_Link1_assy.obj" />
				<!--<mesh filename="asset/panda/link1.stl" />-->
            </geometry>
        </visual>
        <inertial>
            <origin rpy="0 0 0" xyz="0.003875 0.002081 -0.04762" />
            <mass value="4.970684" />
			<inertia ixx="0.70337" ixy="0" ixz="0" iyy="0.70661" iyz="0" izz="0.0091170" />
        </inertial>
    </link>
    <!-- Joint 2 from link 1 to 2 -->
    <joint name="panda_joint2" type="revolute">
        <origin rpy="-1.57079632679 0 0" xyz="0 0 0" />
        <parent link="panda_link1" />
        <child link="panda_link2" />
        <axis xyz="0 0 1" />
        <!-- <limit effort="87" lower="-1.7628" upper="1.7628" velocity="2.1750" /> -->
        <dynamics damping="1.0" />
    </joint>
    <!-- Panda link 2 -->
    <link name="panda_link2">
        <visual>
            <geometry>
                <mesh filename="franka/Franka_Link2_assy OBJ/Franka_Link2_assy.obj" />
				<!--<mesh filename="asset/panda/link2.stl" />-->
            </geometry>
        </visual>
        <inertial>
            <origin rpy="0 0 0" xyz="-0.003141 -0.02872 0.003495" />
            <mass value="0.646926" />
            <inertia ixx="0.0079620" ixy="0.0" ixz="0.0" iyy="0.02811" iyz="0.0" izz="0.025995" />
        </inertial>
    </link>
    <!-- Joint 3 from link 2 to 3 -->
    <joint name="panda_joint3" type="revolute">
        <origin rpy="1.57079632679 0 0" xyz="0 -0.316 0" />
        <parent link="panda_link2" />
        <child link="panda_link3" />
        <axis xyz="0 0 1" />
        <!-- <limit effort="87" lower="-2.8973" upper="2.8973" velocity="2.1750" /> -->
        <dynamics damping="1.0" />
    </joint>
    <!-- Panda link 3 -->
    <link name="panda_link3">
        <visual>
            <geometry>
                <mesh filename="franka/Franka_Link3_assy OBJ/Franka_Link3_assy.obj" />
				<!--<mesh filename="asset/panda/link3.stl" />-->
			</geometry>
        </visual>
        <inertial>
            <origin rpy="0 0 0" xyz="2.7518e-2 3.9252e-2 -6.6502e-2" />
            <mass value="3.228604" />
			<inertia ixx="0.037242" ixy="0.0" ixz="0.0" iyy="0.036155" iyz="0.0" izz="0.01083" />
        </inertial>
    </link>
    <!-- Joint 4 from link 3 to 4 -->
    <joint name="panda_joint4" type="revolute">
        <origin rpy="1.57079632679 0 0" xyz="0.0825 0 0" />
        <parent link="panda_link3" />
        <child link="panda_link4" />
        <axis xyz="0 0 1" />
        <!-- <limit effort="87" lower="-3.0718" upper="-0.0698" velocity="2.1750" /> -->
        <dynamics damping="1.0" />
    </joint>
    <!-- Panda link 4 -->
    <link name="panda_link4">
        <visual>
            <geometry>
                <mesh filename="franka/Franka_Link4_assy OBJ/Franka_Link4_assy.obj" />
				<!--<mesh filename="asset/panda/link4.stl" />-->
            </geometry>
        </visual>
        <inertial>
			<origin rpy="0 0 0" xyz="-5.317e-2 1.04419e-1 2.7454e-2" />
            <mass value="3.587895" />
            <inertia ixx="2.5853e-2" ixy="0.0" ixz="0.0" iyy="1.9552e-2" iyz="0.0" izz="8.627e-3" />
        </inertial>
    </link>
    <!-- Joint 5 from link 4 to 5 -->
    <joint name="panda_joint5" type="revolute">
        <origin rpy="-1.57079632679 0 0" xyz="-0.0825 0.384 0" />
        <parent link="panda_link4" />
        <child link="panda_link5" />
        <axis xyz="0 0 1" />
        <!-- <limit effort="12" lower="-2.8973" upper="2.8973" velocity="2.6100" /> -->
        <dynamics damping="1.0" />
    </joint>
    <!-- Panda link 5 -->
    <link name="panda_link5">
        <visual>
            <geometry>
				<mesh filename="franka/Franka_Link5_assy OBJ/Franka_Link5_assy.obj" />
				<!--<mesh filename="asset/panda/link5.stl" />-->
            </geometry>
        </visual>
        <inertial>
            <origin rpy="0 0 0" xyz="-1.1953e-2 4.1065e-2 -3.8437e-2" />
            <mass value="1.225946" />
            <inertia ixx="3.5549e-2" ixy="0.0" ixz="0.0" iyy="2.9474e-2" iyz="0.0" izz="8.627e-3" />
        </inertial>
    </link>
    <!-- Joint 6 from link 5 to 6 -->
    <joint name="panda_joint6" type="revolute">
        <origin rpy="1.57079632679 0 0" xyz="0 0 0" />
        <parent link="panda_link5" />
        <child link="panda_link6" />
        <axis xyz="0 0 1" />
        <!-- <limit effort="12" lower="-0.0175" upper="3.7525" velocity="2.6100" /> -->
        <dynamics damping="1.0" />
    </joint>
    <!-- Panda link 6 -->
    <link name="panda_link6">
        <visual>
            <geometry>
                <mesh filename="franka/Franka_Link6_assy OBJ/Franka_Link6_assy.obj" />
				<!--<mesh filename="asset/panda/link6.stl" />-->
            </geometry>
        </visual>
		<inertial>
			<origin rpy="0 0 0" xyz="6.0149e-2 -1.4117e-2 -1.0517e-2" />
			<mass value="1.666555" />
			<inertia ixx="1.964e-3" ixy="0.0" ixz="0.0" iyy="4.354e-3" iyz="0.0" izz="5.433e-3" />
		</inertial>
    </link>
    <!-- Joint 7 from link 6 to 7 -->
    <joint name="panda_joint7" type="revolute">
        <origin rpy="1.57079632679 0 0" xyz="0.088 0 0" />
        <parent link="panda_link6" />
        <child link="panda_link7" />
        <axis xyz="0 0 1" />
        <!-- <limit effort="12" lower="-2.8973" upper="2.8973" velocity="2.6100" /> -->
        <dynamics damping="1.0" />
    </joint>
    <!-- Panda link 7 -->
    <link name="panda_link7">
        <visual>
			<origin rpy="0 0 0" xyz="0 0 0" />
            <geometry>
                <mesh filename="franka/Franka_Link7_assy OBJ/Franka_Link7_assy.obj" />
				<!--<mesh filename="asset/panda/link7.stl" />-->
				<!--<box size="0.08 0.08 0.08"/>-->
            </geometry>
        </visual>
        <inertial>
            <origin rpy="0 0 0" xyz="1.0517e-2 -4.252e-3 6.1597e-2" />
            <mass value="7.35522e-01" />
            <inertia ixx="1.2516e-2" ixy="0.0" ixz="0.0" iyy="1.0027e-2" iyz="0.0" izz="4.815e-3" />
        </inertial>
    </link>
	<!-- Robotiq 2F-85 -->
	<joint name="rq85_mount" type="fixed">
		<parent link="panda_link7" />
		<child link="robotiq_85_base_link" />
		<origin xyz="0 0 0.107" rpy="0 0 1.57079632679" />
		<axis xyz="0 0 1" />
	</joint>
	<link name="robotiq_85_base_link">
		<visual>
			<origin xyz="0 0 0" rpy="0 0 0" />
			<geometry>
				<mesh filename="../robotiq2F-85/robotiq_85_base_link_fine.stl" />
			</geometry>
			<!-- <material name="">
				<color rgba="0.1 0.1 0.1 1" />
			</material> -->
		</visual>
		<!-- <collision>
			<origin xyz="0 0 0" rpy="0 0 0" />
			<geometry>
				<mesh filename="../robotiq2F-85/robotiq_85_base_link_coarse.stl" />
			</geometry>
		</collision> -->
		<inertial>
			<origin xyz="0.00021987 -2.3546E-10 0.030163" rpy="0 0 0" />
			<mass value="0.30915" />
			<inertia ixx="0.00028972" ixy="-5.7879E-10" ixz="-1.8543E-06" iyy="0.00030737" iyz="1.682E-12" izz="0.00019914" />
		</inertial>
	</link>
	<joint name="finger_joint" type="revolute">
		<origin xyz="0.0306011444260539 0 0.0627920162695395" rpy="0 0 0" />
		<parent link="robotiq_85_base_link" />
		<child link="left_outer_knuckle" />
		<axis xyz="0 -1 0" />
		<!-- <limit lower="0" upper="0.725" velocity="2.0" effort="1000" /> -->
	</joint>
	<link name="left_outer_knuckle">
		<visual>
			<origin xyz="0 0 0" rpy="0 0 0" />
			<geometry>
				<mesh filename="../robotiq2F-85/outer_knuckle_fine.stl" />
			</geometry>
			<!-- <material name="">
				<color rgba="0.1 0.1 0.1 1" />
			</material> -->
		</visual>
		<!-- <collision>
			<origin xyz="0 0 0" rpy="0 0 0" />
			<geometry>
				<mesh filename="../robotiq2F-85/outer_knuckle_coarse.stl" />
			</geometry>
		</collision> -->
		<inertial>
			<origin xyz="0.0178331863169983 3.68915177224286E-11 0.0021442477325704" rpy="0 0 0" />
			<mass value="0.00684838849434396" />
			<inertia ixx="2.66832029033166E-07" ixy="1.66142314639824E-15" ixz="1.45945633322873E-07" iyy="1.3889233257419E-06" iyz="2.82951161241588E-15" izz="1.26603336914415E-06" />
		</inertial>
	</link>
	<joint name="left_outer_finger_joint" type="fixed">
		<origin xyz="0.0316910442266543 0 -0.00193396375724605" rpy="0 0 0" />
		<parent link="left_outer_knuckle" />
		<child link="left_outer_finger" />
		<axis xyz="0 -1 0" />
	</joint>
	<link name="left_outer_finger">
		<visual>
			<origin xyz="0 0 0" rpy="0 0 0" />
			<geometry>
				<mesh filename="../robotiq2F-85/outer_finger_fine.stl" />
			</geometry>
			<!-- <material name="">
				<color rgba="0.1 0.1 0.1 1" />
			</material> -->
		</visual>
		<!-- <collision>
			<origin xyz="0 0 0" rpy="0 0 0" />
			<geometry>
				<mesh filename="../robotiq2F-85/outer_finger_coarse.stl" />
			</geometry>
		</collision> -->
		<inertial>
			<origin xyz="0.00131451599174296 2.88942057994543E-15 0.0215404163180413" rpy="0 0 0" />
			<mass value="0.0273093985570947" />
			<inertia ixx="8.51629628283022E-06" ixy="2.58174336207405E-19" ixz="3.83829504344079E-07" iyy="6.9133328065108E-06" iyz="-7.58589926143789E-19" izz="2.25006832221981E-06" />
		</inertial>
	</link>
	<joint name="left_inner_knuckle_joint" type="revolute"> 
		<origin xyz="0.0127000000001501 0 0.0693074999999639" rpy="0 0 0" />
		<parent link="robotiq_85_base_link" />
		<child link="left_inner_knuckle" />
		<axis xyz="0 -1 0" />
		<!-- <limit lower="0" upper="0.8757" velocity="2.0" effort="1000" /> -->
		<mimic joint="finger_joint" multiplier="1" offset="0" />
	</joint>
	<link name="left_inner_knuckle">
		<visual>
			<origin xyz="0 0 0" rpy="0 0 0" />
			<geometry>
				<mesh filename="../robotiq2F-85/inner_knuckle_fine.stl" />
			</geometry>
			<!-- <material name="">
				<color rgba="0.1 0.1 0.1 1" />
			</material> -->
		</visual>
		<!-- <collision>
			<origin xyz="0 0 0" rpy="0 0 0" />
			<geometry>
				<mesh filename="../robotiq2F-85/inner_knuckle_coarse.stl" />
			</geometry>
		</collision> -->
		<inertial>
			<origin xyz="0.017097546626628 -3.93808524389535E-10 0.0224918438201868" rpy="0 0 0" />
			<mass value="0.0110930853895903" />
			<inertia ixx="4.23392770691541E-06" ixy="5.748978936968E-15" ixz="1.78855677119788E-06" iyy="3.96548790524392E-06" iyz="1.05464666369669E-14" izz="3.24068002883007E-06" />
		</inertial>
	</link>
	<joint name="left_inner_finger_joint" type="revolute">
		<origin xyz="0.034585310861294 0 0.0454970193817975" rpy="0 0 0" />
		<parent link="left_inner_knuckle" />
		<child link="left_inner_finger" />
		<axis xyz="0 -1 0" />
		<!-- <limit lower="0" upper="0.8757" velocity="2.0" effort="1000" /> -->
		<mimic joint="finger_joint" multiplier="-1" offset="0" />
	</joint>
	<link name="left_inner_finger">
		<visual>
			<origin xyz="0 0 0" rpy="0 0 0" />
			<geometry>
				<mesh filename="../robotiq2F-85/inner_finger_fine.stl" />
			</geometry>
			<!-- <material name="">
				<color rgba="0.1 0.1 0.1 1" />
			</material> -->
		</visual>
		<collision>
			<origin xyz="0 0 0" rpy="0 0 0" />
			<geometry>
				<mesh filename="../robotiq2F-85/inner_finger_coarse.obj" />
			</geometry>
		</collision>
		<inertial>
			<origin xyz="0.0060275613594574 -6.29183141465421E-15 0.00669925693133241" rpy="0 0 0" />
			<mass value="0.00724255346165745" />
			<inertia ixx="1.47824274053603E-06" ixy="-3.94884463570303E-19" ixz="-3.45268847648622E-07" iyy="1.70064480838395E-06" iyz="3.5059838910097E-19" izz="4.77151336838364E-07" />
		</inertial>
	</link>
	<joint name="right_outer_knuckle_joint" type="revolute">
		<origin xyz="-0.0306011444258893 0 0.0627920162695395" rpy="0 0 3.14159265358979" />
		<parent link="robotiq_85_base_link" />
		<child link="right_outer_knuckle" />
		<axis xyz="0 1 0" />
		<!-- <limit lower="-0.8757" upper="0" velocity="2.0" effort="1000" /> -->
		<mimic joint="finger_joint" multiplier="-1" offset="0" />
	</joint>
	<link name="right_outer_knuckle">
		<inertial>
			<origin xyz="0.0178097074051638 3.60493211424024E-11 0.00233123458346721" rpy="0 0 0" />
			<mass value="0.00684838849401352" />
			<inertia ixx="2.70004361573169E-07" ixy="1.59579467624491E-15" ixz="1.56396493788199E-07" iyy="1.38892332558312E-06" iyz="2.82357800318817E-15" izz="1.26286103637978E-06" />
		</inertial>
		<visual>
			<origin xyz="0 0 0" rpy="0 0 0" />
			<geometry>
				<mesh filename="../robotiq2F-85/outer_knuckle_fine.stl" />
			</geometry>
			<!-- <material name="">
				<color rgba="0.1 0.1 0.1 1" />
			</material> -->
		</visual>
		<!-- <collision>
			<origin xyz="0 0 0" rpy="0 0 0" />
			<geometry>
				<mesh filename="../robotiq2F-85/outer_knuckle_coarse.stl" />
			</geometry>
		</collision> -->
	</link>
	<joint name="right_outer_finger_joint" type="fixed">
		<origin xyz="0.0317095909367246 0 -0.0016013564954687" rpy="0 0 0" />
		<parent link="right_outer_knuckle" />
		<child link="right_outer_finger" />
		<axis xyz="0 1 0" />
	</joint>
	<link name="right_outer_finger">
		<visual>
			<origin xyz="0 0 0" rpy="0 0 0" />
			<geometry>
				<mesh filename="../robotiq2F-85/outer_finger_fine.stl" />
			</geometry>
			<!-- <material name="">
				<color rgba="0.1 0.1 0.1 1" />
			</material> -->
		</visual>
		<!-- <collision>
			<origin xyz="0 0 0" rpy="0 0 0" />
			<geometry>
				<mesh filename="../robotiq2F-85/outer_finger_coarse.stl" />
			</geometry>
		</collision> -->
		<inertial>
			<origin xyz="0.00108844269639009 -2.611488350845E-15 0.0215530225245502" rpy="0 0 0" />
			<mass value="0.0273093985570947" />
			<inertia ixx="8.52366028592721E-06" ixy="3.41683380899422E-19" ixz="3.18003675694284E-07" iyy="6.91333280651081E-06" iyz="7.37726682706417E-19" izz="2.24270431912283E-06" />
		</inertial>
	</link>
	<joint name="right_inner_knuckle_joint" type="revolute">
		<origin xyz="-0.0126999999998499 0 0.0693075000000361" rpy="0 0 3.14159265358979" />
		<parent link="robotiq_85_base_link" />
		<child link="right_inner_knuckle" />
		<axis xyz="0 1 0" />
		<!-- <limit lower="-0.8757" upper="0" velocity="2.0" effort="1000" /> -->
		<mimic joint="finger_joint" multiplier="-1" offset="0" />
	</joint>
	<link name="right_inner_knuckle">
		<visual>
			<origin xyz="0 0 0" rpy="0 0 0" />
			<geometry>
				<mesh filename="../robotiq2F-85/inner_knuckle_fine.stl" />
			</geometry>
			<!-- <material name="">
				<color rgba="0.1 0.1 0.1 1" />
			</material> -->
		</visual>
		<!-- <collision>
			<origin xyz="0 0 0" rpy="0 0 0" />
			<geometry>
				<mesh filename="../robotiq2F-85/inner_knuckle_coarse.stl" />
			</geometry>
		</collision> -->
		<inertial>
			<origin xyz="0.0168606186773776 3.93808471820465E-10 0.0226699950793434" rpy="0 0 0" />
			<mass value="0.0110930853895903" />
			<inertia ixx="4.27134775939882E-06" ixy="-8.53568456728898E-15" ixz="1.77774229944246E-06" iyy="3.96548790524392E-06" iyz="-8.45108024914164E-15" izz="3.20325997634666E-06" />
		</inertial>
	</link>
	<joint name="right_inner_finger_joint" type="revolute">
		<origin xyz="0.0341060475457406 0 0.0458573878541688" rpy="0 0 0" />
		<parent link="right_inner_knuckle" />
		<child link="right_inner_finger" />
		<axis xyz="0 1 0" />
		<!-- <limit lower="-0.8757" upper="0" velocity="2.0" effort="1000" /> -->
		<mimic joint="finger_joint" multiplier="1" offset="0" />
	</joint>
	<link name="right_inner_finger">
		<visual>
			<origin xyz="0 0 0" rpy="0 0 0" />
			<geometry>
				<mesh filename="../robotiq2F-85/inner_finger_fine.stl" />
			</geometry>
			<!-- <material name="">
				<color rgba="0.1 0.1 0.1 1" />
			</material> -->
		</visual>
		<collision>
			<origin xyz="0 0 0" rpy="0 0 0" />
			<geometry>
				<mesh filename="../robotiq2F-85/inner_finger_coarse.obj" />
			</geometry>
		</collision>
		<inertial>
			<origin xyz="0.00602756228812038 -6.47284509480176E-15 0.00669925609578108" rpy="0 0 0" />
			<mass value="0.00724255346165744" />
			<inertia ixx="1.47824283625957E-06" ixy="-3.95952064019123E-19" ixz="-3.45268708875543E-07" iyy="1.70064480838394E-06" iyz="3.55286507960029E-19" izz="4.77151241114822E-07" />
		</inertial>
	</link>
	
</robot>
