<?xml version="1.0" encoding="utf-8" ?>
<robot name="pallegro">
	<!-- Panda link 0 -->
    <link name="panda_link0">
        <visual>
            <geometry>
                <mesh filename="franka/Franka_Link0_assy OBJ/Franka_Link0_assy.obj" />
				<!--<mesh filename="asset/panda/link0.stl" />-->
            </geometry>
        </visual>
        <inertial>
            <origin rpy="0 0 0" xyz="0 0 0" />
            <mass value="2.9411" />
			<inertia ixx="0.00315" ixy="0.0" ixz="0.0" iyy="0.00388" iyz="0.0" izz="0.004285" />
        </inertial>
    </link>
    <!-- Joint 1 from link 0 to 1 -->
    <joint name="panda_joint1" type="revolute">
        <origin rpy="0 0 0" xyz="0 0 0.333" />
        <parent link="panda_link0" />
        <child link="panda_link1" />
        <axis xyz="0 0 1" />
        <limit effort="87" lower="-2.8973" upper="2.8973" velocity="2.1750" />
        <dynamics damping="1.0" friction="10" />
    </joint>
    <!-- Panda link 1 -->
    <link name="panda_link1">
        <visual>
            <geometry>
                <mesh filename="franka/Franka_Link1_assy OBJ/Franka_Link1_assy.obj" />
				<!--<mesh filename="asset/panda/link1.stl" />-->
            </geometry>
        </visual>
        <inertial>
            <origin rpy="0 0 0" xyz="0.003875 0.002081 -0.04762" />
            <mass value="4.970684" />
			<inertia ixx="0.70337" ixy="0" ixz="0" iyy="0.70661" iyz="0" izz="0.0091170" />
        </inertial>
    </link>
    <!-- Joint 2 from link 1 to 2 -->
    <joint name="panda_joint2" type="revolute">
        <origin rpy="-1.57079632679 0 0" xyz="0 0 0" />
        <parent link="panda_link1" />
        <child link="panda_link2" />
        <axis xyz="0 0 1" />
        <limit effort="87" lower="-1.7628" upper="1.7628" velocity="2.1750" />
        <dynamics damping="1.0" />
    </joint>
    <!-- Panda link 2 -->
    <link name="panda_link2">
        <visual>
            <geometry>
                <mesh filename="franka/Franka_Link2_assy OBJ/Franka_Link2_assy.obj" />
				<!--<mesh filename="asset/panda/link2.stl" />-->
            </geometry>
        </visual>
        <inertial>
            <origin rpy="0 0 0" xyz="-0.003141 -0.02872 0.003495" />
            <mass value="0.646926" />
            <inertia ixx="0.0079620" ixy="0.0" ixz="0.0" iyy="0.02811" iyz="0.0" izz="0.025995" />
        </inertial>
    </link>
    <!-- Joint 3 from link 2 to 3 -->
    <joint name="panda_joint3" type="revolute">
        <origin rpy="1.57079632679 0 0" xyz="0 -0.316 0" />
        <parent link="panda_link2" />
        <child link="panda_link3" />
        <axis xyz="0 0 1" />
        <limit effort="87" lower="-2.8973" upper="2.8973" velocity="2.1750" />
        <dynamics damping="1.0" />
    </joint>
    <!-- Panda link 3 -->
    <link name="panda_link3">
        <visual>
            <geometry>
                <mesh filename="franka/Franka_Link3_assy OBJ/Franka_Link3_assy.obj" />
				<!--<mesh filename="asset/panda/link3.stl" />-->
			</geometry>
        </visual>
        <inertial>
            <origin rpy="0 0 0" xyz="2.7518e-2 3.9252e-2 -6.6502e-2" />
            <mass value="3.228604" />
			<inertia ixx="0.037242" ixy="0.0" ixz="0.0" iyy="0.036155" iyz="0.0" izz="0.01083" />
        </inertial>
    </link>
    <!-- Joint 4 from link 3 to 4 -->
    <joint name="panda_joint4" type="revolute">
        <origin rpy="1.57079632679 0 0" xyz="0.0825 0 0" />
        <parent link="panda_link3" />
        <child link="panda_link4" />
        <axis xyz="0 0 1" />
        <limit effort="87" lower="-3.0718" upper="-0.0698" velocity="2.1750" />
        <dynamics damping="1.0" />
    </joint>
    <!-- Panda link 4 -->
    <link name="panda_link4">
        <visual>
            <geometry>
                <mesh filename="franka/Franka_Link4_assy OBJ/Franka_Link4_assy.obj" />
				<!--<mesh filename="asset/panda/link4.stl" />-->
            </geometry>
        </visual>
        <inertial>
			<origin rpy="0 0 0" xyz="-5.317e-2 1.04419e-1 2.7454e-2" />
            <mass value="3.587895" />
            <inertia ixx="2.5853e-2" ixy="0.0" ixz="0.0" iyy="1.9552e-2" iyz="0.0" izz="8.627e-3" />
        </inertial>
    </link>
    <!-- Joint 5 from link 4 to 5 -->
    <joint name="panda_joint5" type="revolute">
        <origin rpy="-1.57079632679 0 0" xyz="-0.0825 0.384 0" />
        <parent link="panda_link4" />
        <child link="panda_link5" />
        <axis xyz="0 0 1" />
        <limit effort="12" lower="-2.8973" upper="2.8973" velocity="2.6100" />
        <dynamics damping="1.0" />
    </joint>
    <!-- Panda link 5 -->
    <link name="panda_link5">
        <visual>
            <geometry>
				<mesh filename="franka/Franka_Link5_assy OBJ/Franka_Link5_assy.obj" />
				<!--<mesh filename="asset/panda/link5.stl" />-->
            </geometry>
        </visual>
        <inertial>
            <origin rpy="0 0 0" xyz="-1.1953e-2 4.1065e-2 -3.8437e-2" />
            <mass value="1.225946" />
            <inertia ixx="3.5549e-2" ixy="0.0" ixz="0.0" iyy="2.9474e-2" iyz="0.0" izz="8.627e-3" />
        </inertial>
    </link>
    <!-- Joint 6 from link 5 to 6 -->
    <joint name="panda_joint6" type="revolute">
        <origin rpy="1.57079632679 0 0" xyz="0 0 0" />
        <parent link="panda_link5" />
        <child link="panda_link6" />
        <axis xyz="0 0 1" />
        <limit effort="12" lower="-0.0175" upper="3.7525" velocity="2.6100" />
        <dynamics damping="1.0" />
    </joint>
    <!-- Panda link 6 -->
    <link name="panda_link6">
        <visual>
            <geometry>
                <mesh filename="franka/Franka_Link6_assy OBJ/Franka_Link6_assy.obj" />
				<!--<mesh filename="asset/panda/link6.stl" />-->
            </geometry>
        </visual>
		<inertial>
			<origin rpy="0 0 0" xyz="6.0149e-2 -1.4117e-2 -1.0517e-2" />
			<mass value="1.666555" />
			<inertia ixx="1.964e-3" ixy="0.0" ixz="0.0" iyy="4.354e-3" iyz="0.0" izz="5.433e-3" />
		</inertial>
    </link>
    <!-- Joint 7 from link 6 to 7 -->
    <joint name="panda_joint7" type="revolute">
        <origin rpy="1.57079632679 0 0" xyz="0.088 0 0" />
        <parent link="panda_link6" />
        <child link="panda_link7" />
        <axis xyz="0 0 1" />
        <limit effort="12" lower="-2.8973" upper="2.8973" velocity="2.6100" />
        <dynamics damping="1.0" />
    </joint>
    <!-- Panda link 7 -->
    <link name="panda_link7">
        <visual>
			<origin rpy="0 0 0" xyz="0 0 0" />
            <geometry>
                <mesh filename="franka/Franka_Link7_assy OBJ/Franka_Link7_assy.obj" />
				<!--<mesh filename="asset/panda/link7.stl" />-->
				<!--<box size="0.08 0.08 0.08"/>-->
            </geometry>
        </visual>
        <inertial>
            <origin rpy="0 0 0" xyz="1.0517e-2 -4.252e-3 6.1597e-2" />
            <mass value="7.35522e-01" />
            <inertia ixx="1.2516e-2" ixy="0.0" ixz="0.0" iyy="1.0027e-2" iyz="0.0" izz="4.815e-3" />
        </inertial>
    </link>
	<!-- Fixed joint from link 7 to allegro palm -->
	<joint name="panda_joint7" type="fixed">
		<origin rpy="0 0 0" xyz="0 0 0.202" />
		<parent link="panda_link7" />
		<child link="allegro_palm" />
		<axis xyz="0 0 1" />
	</joint>
	<!--Allegro Palm-->
	<link name="allegro_palm">
		<visual>
			<origin rpy="0 0 0" xyz="0 0 0" />
			<geometry>
				<mesh filename="../allegro/base_link.obj" />
			</geometry>
			<material name="black">
				<color rgba="0.2 0.2 0.2 1"/>
			</material>
		</visual>
		<collision>
			<origin rpy="0 0 0" xyz="-0.009300 0 -0.0475"/>
			<geometry>
				<box size="0.0408 0.1130 0.095"/>
			</geometry>
		</collision>
		<inertial>
			<origin rpy="0 0 0" xyz="0 0 0"/>
			<mass value="0.4154"/>
			<inertia ixx="0.00208916" ixy="-3.63457e-06" ixz="0.000223277" iyy="0.00182848" iyz="-1.75634e-05" izz="0.000482459"/>
		</inertial>
	</link>
	<link name="allegro_link0">
		<visual>
			<geometry>
				<mesh filename="../allegro/link_0.0.obj"/>
			</geometry>
			<material name="black"/>
		</visual>
		<!--
		<collision>
			<geometry>
				<box size="0.0196 0.0275 0.0164"/>
			</geometry>
			<origin rpy="0 0 0" xyz="0 0 0.0082"/>
		</collision>
		-->
		<inertial>
			<mass value="0.0119"/>
			<origin rpy="0 0 0" xyz="0 0 0"/>
			<inertia ixx="1.95377e-06" ixy="3.03372e-09" ixz="8.92323e-08" iyy="1.17908e-06" iyz="-3.7069e-08" izz="1.49673e-06"/>
		</inertial>
	</link>
	<joint name="allegro_joint0" type="revolute">
		<axis xyz="0 0 1"/>
		<limit effort="0.7" lower="-0.47" upper="0.47" velocity="7"/>
		<parent link="allegro_palm"/>
		<child link="allegro_link0"/>
		<origin rpy="-0.08726646255 0 0" xyz="0 0.0435 -0.001542"/>
		<dynamics damping="1.5e-2" friction="10"/>
	</joint>
	<link name="allegro_link1">
		<visual>
			<geometry>
			<mesh filename="../allegro/link_1.0.obj"/>
			</geometry>
			<material name="black"/>
		</visual>
		<collision>
			<geometry>
			<box size="0.0196 0.0275 0.054"/>
			</geometry>
			<origin rpy="0 0 0" xyz="0 0 0.027"/>
		</collision>
		<inertial>
			<mass value="0.065"/>
			<origin rpy="0 0 0" xyz="0 0 0"/>
			<inertia ixx="7.19218e-05" ixy="0" ixz="0" iyy="7.4377e-05" iyz="7.32186e-07" izz="5.40622e-06"/>
		</inertial>
	</link>
	<joint name="allegro_joint1" type="revolute">
		<limit effort="0.7" lower="-0.196" upper="1.61" velocity="7"/>
		<axis xyz="0 1 0"/>
		<parent link="allegro_link0"/>
		<child link="allegro_link1"/>
		<origin xyz="0 0 0.0164"/>
		<dynamics damping="1.5e-2" friction="5"/>
	</joint>
	<link name="allegro_link2">
		<visual>
			<geometry>
				<mesh filename="../allegro/link_2.0.obj"/>
			</geometry>
			<material name="black"/>
		</visual>
		<collision>
			<geometry>
				<box size="0.0196 0.0275 0.0384"/>
			</geometry>
			<origin rpy="0 0 0" xyz="0 0 0.0192"/>
		</collision>
		<inertial>
			<mass value="0.0355"/>
			<origin rpy="0 0 0" xyz="0 0 0"/>
			<inertia ixx="3.16925e-05" ixy="1.07094e-09" ixz="-4.91273e-09" iyy="3.10516e-05" iyz="3.87549e-08" izz="3.20319e-06"/>
		</inertial>
	</link>
	<joint name="allegro_joint2" type="revolute">
		<axis xyz="0 1 0"/>
		<limit effort="0.7" lower="-0.174" upper="1.709" velocity="7"/>
		<parent link="allegro_link1"/>
		<child link="allegro_link2"/>
		<origin xyz="0 0 0.054"/>
		<dynamics damping="1.5e-2" friction="10"/>
	</joint>
	<link name="allegro_link3">
		<visual>
			<geometry>
				<mesh filename="../allegro/link_3.0.obj"/>
			</geometry>
			<material name="black"/>
		</visual>
		<collision>
			<geometry>
				<box size="0.0196 0.0275 0.0267"/>
			</geometry>
			<origin rpy="0 0 0" xyz="0 0 0.01335"/>
		</collision>
		<inertial>
			<mass value="0.0096"/>
			<origin rpy="0 0 0" xyz="0 0 0"/>
			<inertia ixx="2.13975e-06" ixy="1.59554e-09" ixz="-7.47528e-09" iyy="1.52036e-06" iyz="-9.89336e-09" izz="1.20271e-06"/>
		</inertial>
	</link>
	<joint name="allegro_joint3" type="revolute">
		<axis xyz="0 1 0"/>
		<limit effort="0.7" lower="-0.227" upper="1.618" velocity="7"/>
		<parent link="allegro_link2"/>
		<child link="allegro_link3"/>
		<origin xyz="0 0 0.0384"/>
		<dynamics damping="1.5e-2" friction="12"/>
	</joint>
	<link name="allegro_link3_tip">
		<visual>
			<geometry>
				<mesh filename="../allegro/link_3.0_tip.obj"/>
			</geometry>
			<material name="white">
				<color rgba=".9 .9 .9 1"/>
			</material>
		</visual>
		<collision>
			<geometry>
				<sphere radius="0.012"/>
			</geometry>
		</collision>
		<inertial>
			<mass value="0.0168"/>
			<origin rpy="0 0 0" xyz="0 0 0"/>
			<inertia ixx="1.19599e-05" ixy="0" ixz="0" iyy="1.19598e-05" iyz="0" izz="1.10345e-06"/>
		</inertial>
	</link>
	<joint name="allegro_joint3_tip" type="fixed">
		<parent link="allegro_link3"/>
		<child link="allegro_link3_tip"/>
		<origin rpy="0 0 0" xyz="0 0 0.0267"/>
	</joint>
	<link name="allegro_link4">
		<visual>
			<geometry>
				<mesh filename="../allegro/link_0.0.obj"/>
			</geometry>
			<material name="black"/>
		</visual>
		<!--
		<collision>
			<geometry>
				<box size="0.0196 0.0275 0.0164"/>
			</geometry>
			<origin rpy="0 0 0" xyz="0 0 0.0082"/> 
		</collision>
		-->
		<inertial>
			<mass value="0.0119"/>
			<origin rpy="0 0 0" xyz="0 0 0"/>
			<inertia ixx="1.95377e-06" ixy="3.03372e-09" ixz="8.92323e-08" iyy="1.17908e-06" iyz="-3.7069e-08" izz="1.49673e-06"/>
		</inertial>
	</link>
	<joint name="allegro_joint4" type="revolute">
		<axis xyz="0 0 1"/>
		<limit effort="0.7" lower="-0.47" upper="0.47" velocity="7"/>
		<parent link="allegro_palm"/>
		<child link="allegro_link4"/>
		<origin rpy="0.0 0 0" xyz="0 0 0.0007"/>
		<dynamics damping="1.5e-2" friction="10"/>
	</joint>
	<link name="allegro_link5">
		<visual>
			<geometry>
			<mesh filename="../allegro/link_1.0.obj"/>
			</geometry>
			<material name="black"/>
		</visual>
		<collision>
			<geometry>
			<box size="0.0196 0.0275 0.054"/>
			</geometry>
			<origin rpy="0 0 0" xyz="0 0 0.027"/>
		</collision>
		<inertial>
			<mass value="0.065"/>
			<origin rpy="0 0 0" xyz="0 0 0"/>
			<inertia ixx="7.19218e-05" ixy="0" ixz="0" iyy="7.4377e-05" iyz="7.32186e-07" izz="5.40622e-06"/>
		</inertial>
	</link>
	<joint name="allegro_joint5" type="revolute">
		<limit effort="0.7" lower="-0.196" upper="1.61" velocity="7"/>
		<axis xyz="0 1 0"/>
		<parent link="allegro_link4"/>
		<child link="allegro_link5"/>
		<origin xyz="0 0 0.0164"/>
		<dynamics damping="1.5e-2" friction="5"/>
	</joint>
	<link name="allegro_link6">
		<visual>
			<geometry>
				<mesh filename="../allegro/link_2.0.obj"/>
			</geometry>
			<material name="black"/>
		</visual>
		<collision>
			<geometry>
			<box size="0.0196 0.0275 0.0384"/>
				</geometry>
			<origin rpy="0 0 0" xyz="0 0 0.0192"/>
		</collision>
		<inertial>
			<mass value="0.0355"/>
			<origin rpy="0 0 0" xyz="0 0 0"/>
			<inertia ixx="3.16925e-05" ixy="1.07094e-09" ixz="-4.91273e-09" iyy="3.10516e-05" iyz="3.87549e-08" izz="3.20319e-06"/>
		</inertial>
	</link>
	<joint name="allegro_joint6" type="revolute">
		<axis xyz="0 1 0"/>
		<limit effort="0.7" lower="-0.174" upper="1.709" velocity="7"/>
		<parent link="allegro_link5"/>
		<child link="allegro_link6"/>
		<origin xyz="0 0 0.054"/>
		<dynamics damping="1.5e-2" friction="10"/>
	</joint>
	<link name="allegro_link7">
		<visual>
			<geometry>
			<mesh filename="../allegro/link_3.0.obj"/>
			</geometry>
			<material name="black"/>
		</visual>
		<collision>
			<geometry>
			<box size="0.0196 0.0275 0.0267"/>
			</geometry>
			<origin rpy="0 0 0" xyz="0 0 0.01335"/>
		</collision>
		<inertial>
			<mass value="0.0096"/>
			<origin rpy="0 0 0" xyz="0 0 0"/>
			<inertia ixx="2.13975e-06" ixy="1.59554e-09" ixz="-7.47528e-09" iyy="1.52036e-06" iyz="-9.89336e-09" izz="1.20271e-06"/>
		</inertial>
	</link>
	<joint name="allegro_joint7" type="revolute">
		<axis xyz="0 1 0"/>
		<limit effort="0.7" lower="-0.227" upper="1.618" velocity="7"/>
		<parent link="allegro_link6"/>
		<child link="allegro_link7"/>
		<origin xyz="0 0 0.0384"/>
		<dynamics damping="1.5e-2" friction="12"/>
	</joint>
	<link name="allegro_link7_tip">
		<visual>
			<geometry>
				<mesh filename="../allegro/link_3.0_tip.obj"/>
			</geometry>
			<material name="white">
				<color rgba=".9 .9 .9 1"/>
			</material>
		</visual>
		<collision>
			<geometry>
				<sphere radius="0.012"/>
			</geometry>
		</collision>
		<inertial>
			<mass value="0.0168"/>
			<origin rpy="0 0 0" xyz="0 0 0"/>
			<inertia ixx="1.19599e-05" ixy="0" ixz="0" iyy="1.19598e-05" iyz="0" izz="1.10345e-06"/>
		</inertial>
	</link>
	<joint name="allegro_joint7_tip" type="fixed">
		<parent link="allegro_link7"/>
		<child link="allegro_link7_tip"/>
		<origin rpy="0 0 0" xyz="0 0 0.0267"/>
	</joint>
	<link name="allegro_link8">
		<visual>
			<geometry>
				<mesh filename="../allegro/link_0.0.obj"/>
			</geometry>
			<material name="black"/>
		</visual>
		<!--
		<collision>
			<geometry>
				<box size="0.0196 0.0275 0.0164"/>
			</geometry>
			<origin rpy="0 0 0" xyz="0 0 0.0082"/>
		</collision>
		-->
		<inertial>
			<mass value="0.0119"/>
			<origin rpy="0 0 0" xyz="0 0 0"/>
			<inertia ixx="1.95377e-06" ixy="3.03372e-09" ixz="8.92323e-08" iyy="1.17908e-06" iyz="-3.7069e-08" izz="1.49673e-06"/>
		</inertial>
	</link>
	<joint name="allegro_joint8" type="revolute">
		<axis xyz="0 0 1"/>
		<limit effort="0.7" lower="-0.47" upper="0.47" velocity="7"/>
		<parent link="allegro_palm"/>
		<child link="allegro_link8"/>
		<origin rpy="0.08726646255 0 0" xyz="0 -0.0435 -0.001542"/>
		<dynamics damping="1.5e-2" friction="10"/>
	</joint>
	<link name="allegro_link9">
		<visual>
			<geometry>
				<mesh filename="../allegro/link_1.0.obj"/>
			</geometry>
			<material name="black"/>
		</visual>
		<collision>
			<geometry>
				<box size="0.0196 0.0275 0.054"/>
			</geometry>
			<origin rpy="0 0 0" xyz="0 0 0.027"/>
		</collision>
		<inertial>
			<mass value="0.065"/>
			<origin rpy="0 0 0" xyz="0 0 0"/>
			<inertia ixx="7.19218e-05" ixy="0" ixz="0" iyy="7.4377e-05" iyz="7.32186e-07" izz="5.40622e-06"/>
		</inertial>
	</link>
	<joint name="allegro_joint9" type="revolute">
		<limit effort="0.7" lower="-0.196" upper="1.61" velocity="7"/>
		<axis xyz="0 1 0"/>
		<parent link="allegro_link8"/>
		<child link="allegro_link9"/>
		<origin xyz="0 0 0.0164"/>
		<dynamics damping="1.5e-2" friction="5"/>
	</joint>
	<link name="allegro_link10">
		<visual>
			<geometry>
				<mesh filename="../allegro/link_2.0.obj"/>
			</geometry>
			<material name="black"/>
		</visual>
		<collision>
			<geometry>
				<box size="0.0196 0.0275 0.0384"/>
			</geometry>
			<origin rpy="0 0 0" xyz="0 0 0.0192"/>
		</collision>
		<inertial>
			<mass value="0.0355"/>
			<origin rpy="0 0 0" xyz="0 0 0"/>
			<inertia ixx="3.16925e-05" ixy="1.07094e-09" ixz="-4.91273e-09" iyy="3.10516e-05" iyz="3.87549e-08" izz="3.20319e-06"/>
		</inertial>
	</link>
	<joint name="allegro_joint10" type="revolute">
		<axis xyz="0 1 0"/>
		<limit effort="0.7" lower="-0.174" upper="1.709" velocity="7"/>
		<parent link="allegro_link9"/>
		<child link="allegro_link10"/>
		<origin xyz="0 0 0.054"/>
		<dynamics damping="1.5e-2" friction="10"/>
	</joint>
	<link name="allegro_link11">
		<visual>
			<geometry>
			<mesh filename="../allegro/link_3.0.obj"/>
			</geometry>
			<material name="black"/>
		</visual>
		<collision>
			<geometry>
			<box size="0.0196 0.0275 0.0267"/>
			</geometry>
			<origin rpy="0 0 0" xyz="0 0 0.01335"/>
		</collision>
		<inertial>
			<mass value="0.0096"/>
			<origin rpy="0 0 0" xyz="0 0 0"/>
			<inertia ixx="2.13975e-06" ixy="1.59554e-09" ixz="-7.47528e-09" iyy="1.52036e-06" iyz="-9.89336e-09" izz="1.20271e-06"/>
		</inertial>
	</link>
	<joint name="allegro_joint11" type="revolute">
		<axis xyz="0 1 0"/>
		<limit effort="0.7" lower="-0.227" upper="1.618" velocity="7"/>
		<parent link="allegro_link10"/>
		<child link="allegro_link11"/>
		<origin xyz="0 0 0.0384"/>
		<dynamics damping="1.5e-2" friction="12"/>
	</joint>
	<link name="allegro_link11_tip">
		<visual>
			<geometry>
			<mesh filename="../allegro/link_3.0_tip.obj"/>
			</geometry>
			<material name="white">
			<color rgba=".9 .9 .9 1"/>
			</material>
		</visual>
		<collision>
			<geometry>
				<sphere radius="0.012"/>
			</geometry>
		</collision>
		<inertial>
			<mass value="0.0168"/>
			<origin rpy="0 0 0" xyz="0 0 0"/>
			<inertia ixx="1.19599e-05" ixy="0" ixz="0" iyy="1.19598e-05" iyz="0" izz="1.10345e-06"/>
		</inertial>
	</link>
	<joint name="allegro_joint11_tip" type="fixed">
		<parent link="allegro_link11"/>
		<child link="allegro_link11_tip"/>
		<origin rpy="0 0 0" xyz="0 0 0.0267"/>
	</joint>
	<link name="allegro_link12">
		<visual>
			<geometry>
			<mesh filename="../allegro/link_12.0_right.obj"/>
			</geometry>
			<material name="black">
			<color rgba=".2 .2 .2 1"/>
			</material>
			<origin rpy="0 0 0" xyz="0 0 0"/>
		</visual>
		<!--
		<collision>
			<geometry>
			<box size="0.0358 0.034 0.0455"/>
			</geometry>
			<origin rpy="0 0 0" xyz="-0.0179 0.009 0.0145"/>
		</collision>
		-->
		<inertial>
			<mass value="0.0176"/>
			<origin rpy="0 0 0" xyz="0 0 0"/>
			<inertia ixx="8.13883e-06" ixy="2.55226e-06" ixz="3.89933e-06" iyy="1.31421e-05" iyz="-1.46267e-06" izz="1.00171e-05"/>
		</inertial>
	</link>
	<joint name="allegro_joint12" type="revolute">
		<axis xyz="-1 0 0"/>
		<limit effort="0.7" lower="0.263" upper="1.396" velocity="7"/>
		<parent link="allegro_palm"/>
		<child link="allegro_link12"/>
		<origin rpy="0 -1.65806278845 -1.5707963259" xyz="-0.0182 0.019333 -0.045987"/>
		<dynamics damping="1.5e-2" friction="10"/>
	</joint>
	<link name="allegro_link13">
		<visual>
			<geometry>
				<mesh filename="../allegro/link_13.0.obj"/>
			</geometry>
			<material name="black">
				<color rgba=".2 .2 .2 1"/>
			</material>
		</visual>
		<!--
		<collision>
			<geometry>
				<box size="0.0196 0.0275 0.0177"/>
			</geometry>
			<origin rpy="0 0 0" xyz="0 0 0.00885"/>
		</collision>
		-->
		<inertial>
			<mass value="0.0119"/>
			<origin rpy="0 0 0" xyz="0 0 0"/>
			<inertia ixx="1.9263e-06" ixy="3.05433e-09" ixz="8.86582e-08" iyy="1.15276e-06" iyz="-3.64521e-08" izz="1.4957e-06"/>
		</inertial>
	</link>
	<joint name="allegro_joint13" type="revolute">
		<axis xyz="0 0 1"/>
		<limit effort="0.7" lower="-0.105" upper="1.163" velocity="7"/>
		<parent link="allegro_link12"/>
		<child link="allegro_link13"/>
		<origin xyz="-0.027 0.005 0.0399"/>
		<dynamics damping="1.5e-2" friction="5"/>
	</joint>
	<link name="allegro_link14">
		<visual>
			<geometry>
				<mesh filename="../allegro/link_14.0.obj"/>
			</geometry>
			<material name="black">
			</material>
		</visual>
		<collision>
			<geometry>
				<box size="0.0196 0.0275 0.0514"/>
			</geometry>
			<origin rpy="0 0 0" xyz="0 0 0.0257"/>
		</collision>
		<inertial>
			<mass value="0.038"/>
			<origin rpy="0 0 0" xyz="0 0 0"/>
			<inertia ixx="3.67044e-05" ixy="1.02277e-09" ixz="1.4854e-07" iyy="3.54042e-05" iyz="-3.67203e-08" izz="3.63275e-06"/>
		</inertial>
	</link>
	<joint name="allegro_joint14" type="revolute">
		<axis xyz="0 1 0"/>
		<limit effort="0.7" lower="-0.189" upper="1.644" velocity="7"/>
		<parent link="allegro_link13"/>
		<child link="allegro_link14"/>
		<origin xyz="0 0 0.0177"/>
		<dynamics damping="1.5e-2" friction="10"/>
	</joint>
	<link name="allegro_link15">
		<visual>
			<geometry>
				<mesh filename="../allegro/link_15.0.obj"/>
			</geometry>
			<material name="black">
			</material>
		</visual>
		<collision>
			<geometry>
				<box size="0.0196 0.0275 0.0423"/>
			</geometry>
			<origin rpy="0 0 0" xyz="0 0 0.02115"/>
		</collision>
		<inertial>
			<mass value="0.0388"/>
			<origin rpy="0 0 0" xyz="0 0 0"/>
			<inertia ixx="4.30919e-05" ixy="0" ixz="0" iyy="3.85425e-05" iyz="-3.0146e-08" izz="1.72974e-05"/>
		</inertial>
	</link>
	<joint name="allegro_joint15" type="revolute">
		<axis xyz="0 1 0"/>
		<limit effort="0.7" lower="-0.162" upper="1.719" velocity="7"/>
		<parent link="allegro_link14"/>
		<child link="allegro_link15"/>
		<origin xyz="0 0 0.0514"/>
		<dynamics damping="1.5e-2" friction="12"/>
	</joint>
	<link name="allegro_link15_tip">
		<visual>
			<geometry>
				<mesh filename="../allegro/link_15.0_tip.obj"/>
			</geometry>
			<material name="white">
				<color rgba=".9 .9 .9 1"/>
			</material>
		</visual>
		<collision>
			<geometry>
				<sphere radius="0.012"/>
			</geometry>
			<origin rpy="0 0 0" xyz="0 0 0"/>
		</collision>
		<inertial>
			<mass value="0.0168"/>
			<origin rpy="0 0 0" xyz="0 0 0"/>
			<inertia ixx="1.19599e-05" ixy="0" ixz="0" iyy="1.19598e-05" iyz="0" izz="1.10345e-06"/>
		</inertial>
	</link>
	<joint name="allegro_joint15_tip" type="fixed">
		<parent link="allegro_link15"/>
		<child link="allegro_link15_tip"/>
		<origin rpy="0 0 0" xyz="0 0 0.0423"/>
	</joint>
</robot>
